Workbook

Sheet Dashboard
A1: Duplicate Payment and Fraud Red-Flag Analysis
A2: Accounts Payable analytics in Excel | Forensic / FIRE-style data tests
A3: DATA DISCLOSURE: all vendors, invoices and amounts in this workbook are synthetic (computer-generated, fictional). Anomalies were planted deliberately to demonstrate the tests. No real company data is used.
A5: Key figures
A6: Metric | B6: Value
A7: Total transactions | B7: =COUNTA(Data!$A$2:$A$1534) -> 1533
A8: Total value (INR) | B8: =SUM(Data!$G$2:$G$1534) -> 2.15312e+08
A9: Transactions with at least one flag | B9: =COUNTIF(Data!$R$2:$R$1534,">0") -> 197
A10: % of transactions flagged | B10: =IF(B7=0,0,B9/B7) -> 0.1285062
A11: Value of flagged transactions (INR) | B11: =SUMIF(Data!$R$2:$R$1534,">0",Data!$G$2:$G$1534) -> 23422438
A12: High-risk transactions | B12: =COUNTIF(Data!$S$2:$S$1534,"High") -> 36
A13: Value of high-risk transactions (INR) | B13: =SUMIF(Data!$S$2:$S$1534,"High",Data!$G$2:$G$1534) -> 6286167.8
A15: Red-flag tests
A16: Test | B16: Transactions flagged | C16: Value flagged (INR) | D16: % of transactions
A17: F1 Duplicate invoice | B17: =SUM(Data!$L$2:$L$1534) -> 36 | C17: =SUMIF(Data!$L$2:$L$1534,1,Data!$G$2:$G$1534) -> 6286167.8 | D17: =IF($B$7=0,0,B17/$B$7) -> 0.023483366
A18: F2 Near-duplicate | B18: =SUM(Data!$M$2:$M$1534) -> 32 | C18: =SUMIF(Data!$M$2:$M$1534,1,Data!$G$2:$G$1534) -> 3758507.1 | D18: =IF($B$7=0,0,B18/$B$7) -> 0.020874103
A19: F3 Just below limit | B19: =SUM(Data!$N$2:$N$1534) -> 36 | C19: =SUMIF(Data!$N$2:$N$1534,1,Data!$G$2:$G$1534) -> 1754381.8 | D19: =IF($B$7=0,0,B19/$B$7) -> 0.023483366
A20: F4 Round amount | B20: =SUM(Data!$O$2:$O$1534) -> 25 | C20: =SUMIF(Data!$O$2:$O$1534,1,Data!$G$2:$G$1534) -> 2250000 | D20: =IF($B$7=0,0,B20/$B$7) -> 0.016307893
A21: F5 No PO / GRN | B21: =SUM(Data!$P$2:$P$1534) -> 40 | C21: =SUMIF(Data!$P$2:$P$1534,1,Data!$G$2:$G$1534) -> 5499447.7 | D21: =IF($B$7=0,0,B21/$B$7) -> 0.026092629
A22: F6 Weekend payment | B22: =SUM(Data!$Q$2:$Q$1534) -> 30 | C22: =SUMIF(Data!$Q$2:$Q$1534,1,Data!$G$2:$G$1534) -> 3933933.3 | D22: =IF($B$7=0,0,B22/$B$7) -> 0.019569472
A23: A transaction can fail more than one test, so rows above overlap and should not be added together.
A25: Risk rating
A26: Rating | B26: Transactions | C26: Value (INR) | D26: % of transactions
A27: High | B27: =COUNTIF(Data!$S$2:$S$1534,A27) -> 36 | C27: =SUMIF(Data!$S$2:$S$1534,A27,Data!$G$2:$G$1534) -> 6286167.8 | D27: =IF($B$7=0,0,B27/$B$7) -> 0.023483366
A28: Medium | B28: =COUNTIF(Data!$S$2:$S$1534,A28) -> 108 | C28: =SUMIF(Data!$S$2:$S$1534,A28,Data!$G$2:$G$1534) -> 11012337 | D28: =IF($B$7=0,0,B28/$B$7) -> 0.070450098
A29: Low | B29: =COUNTIF(Data!$S$2:$S$1534,A29) -> 53 | C29: =SUMIF(Data!$S$2:$S$1534,A29,Data!$G$2:$G$1534) -> 6123933.3 | D29: =IF($B$7=0,0,B29/$B$7) -> 0.034572733
A30: Clear | B30: =COUNTIF(Data!$S$2:$S$1534,A30) -> 1336 | C30: =SUMIF(Data!$S$2:$S$1534,A30,Data!$G$2:$G$1534) -> 1.9188956e+08 | D30: =IF($B$7=0,0,B30/$B$7) -> 0.8714938
A32: How to read this workbook
A33: 1. Data: every transaction with six formula-driven red-flag tests, a weighted risk score and a rating.
A34: 2. Assumptions: approval limit, windows and weights are inputs; change them and everything recalculates.
A35: 3. Vendor_Risk and Approver_Analysis: where the flags concentrate. Exceptions: the 30 highest-scoring transactions to investigate first.
A36: 4. Benford: first-digit test on invoice amounts. Findings: results and recommended controls.
A37: Limitation: red flags are indicators, not proof of fraud. Each flagged item needs follow-up with supporting documents.

Sheet Findings
A1: Findings and recommended controls
A2: Result figures are live formulas linked to the Dashboard. Data is synthetic.
A4: Area | B4: What the test found | C4: Why it matters | D4: Recommended control
A5: Duplicate invoices | B5: =Dashboard!B17&" transactions share a vendor and invoice number with another payment (value INR "&TEXT(Dashboard!C17,"#,##0")&")." -> 36 transactions share a vendor and invoice number with another payment (value INR 62,86,168). | C5: Paying the same invoice twice is direct cash loss and is often the first thing recovery audits find. | D5: Hard-block posting when vendor + invoice number already exists; run a monthly duplicate report and recover overpayments.
A6: Near-duplicates | B6: =Dashboard!B18&" transactions match another payment on vendor and amount within "&Assumptions!B5&" days but carry a different invoice number." -> 32 transactions match another payment on vendor and amount within 7 days but carry a different invoice number. | C6: Changing an invoice number is a simple way to get a duplicate past a basic system check. | D6: Add fuzzy matching on vendor + amount + date window; require supporting documents for any match before release.
A7: Just below approval limit | B7: =Dashboard!B19&" transactions fall between INR "&TEXT(Assumptions!B4*(1-Assumptions!B6),"#,##0")&" and INR "&TEXT(Assumptions!B4,"#,##0")&"; see Approver_Analysis for concentration." -> 36 transactions fall between INR 47,500 and INR 50,000; see Approver_Analysis for concentration. | C7: Clusters just under a limit can indicate invoice splitting to avoid higher-level approval. | D7: Review the vendors and approvers involved; consider cumulative-spend limits per vendor per period.
A8: Round-number amounts | B8: =Dashboard!B20&" transactions are exact multiples of INR "&TEXT(Assumptions!B7,"#,##0")&"." -> 25 transactions are exact multiples of INR 10,000. | C8: Genuine invoices are rarely perfectly round. Weak on its own but useful with other flags. | D8: Sample-check supporting invoices for round-amount payments, especially to vendors with other flags.
A9: No PO / GRN | B9: =Dashboard!B21&" transactions lack a PO or a goods receipt (value INR "&TEXT(Dashboard!C21,"#,##0")&")." -> 40 transactions lack a PO or a goods receipt (value INR 54,99,448). | C9: Payment without a PO or GRN bypasses the 3-way match control. | D9: Enforce no-PO-no-pay with a documented exception route; report non-PO spend monthly.
A10: Weekend payments | B10: =Dashboard!B22&" payments have a payment date on a Saturday or Sunday." -> 30 payments have a payment date on a Saturday or Sunday. | C10: Unusual processing times can indicate off-cycle or unauthorised payment runs. | D10: Restrict payment-run scheduling and review any off-cycle release.
A11: Overall priority | B11: =Dashboard!B12&" transactions rate High (value INR "&TEXT(Dashboard!B13,"#,##0")&"); start with the Exceptions sheet." -> 36 transactions rate High (value INR 62,86,168); start with the Exceptions sheet. | C11: Weighted scoring focuses limited investigator time on the items with several red flags. | D11: Investigate High items first, document outcomes, and tune weights using confirmed cases.

Sheet Data
A1: Txn_ID | B1: Vendor_ID | C1: Vendor_Name | D1: Invoice_No | E1: Invoice_Date | F1: Payment_Date | G1: Amount_INR | H1: PO_No | I1: GRN_No | J1: Approver | K1: First_Digit | L1: F1_Duplicate | M1: F2_NearDuplicate | N1: F3_BelowLimit | O1: F4_RoundNo | P1: F5_NoPO_GRN | Q1: F6_Weekend | R1: Risk_Score | S1: Rating | T1: Flags_Triggered
A2: TXN-0001 | B2: V011 | C2: Horizon Travel Desk Pvt Ltd | D2: INV-011-45822 | E2: 45748 | F2: 45769 | G2: 631713.92 | H2: PO463201 | I2: GR463201 | J2: AP-Mgr-05 | K2: =VALUE(LEFT(TEXT(G2,"0"),1)) -> 6 | L2: =IF(COUNTIFS($B$2:$B$1534,B2,$D$2:$D$1534,D2)>1,1,0) -> 0 | M2: =IF(AND(L2=0,COUNTIFS($B$2:$B$1534,B2,$G$2:$G$1534,G2,$E$2:$E$1534,">="&(E2-Assumptions!$B$5),$E$2:$E$1534,"<="&(E2+Assumptions!$B$5))>1),1,0) -> 1 | N2: =IF(AND(G2>=Assumptions!$B$4*(1-Assumptions!$B$6),G2<Assumptions!$B$4),1,0) -> 0 | O2: =IF(AND(G2>=Assumptions!$B$7,MOD(G2,Assumptions!$B$7)=0),1,0) -> 0 | P2: =IF(OR(H2="",I2=""),1,0) -> 0 | Q2: =IF(WEEKDAY(F2,2)>5,1,0) -> 0 | R2: =L2*Assumptions!$B$11+M2*Assumptions!$B$12+N2*Assumptions!$B$13+O2*Assumptions!$B$14+P2*Assumptions!$B$15+Q2*Assumptions!$B$16 -> 3 | S2: =IF(R2>=Assumptions!$B$20,"High",IF(R2>=Assumptions!$B$21,"Medium",IF(R2>=1,"Low","Clear"))) -> Medium | T2: =IF(R2=0,"",IF(L2=1,"Duplicate invoice; ","")&IF(M2=1,"Near-duplicate; ","")&IF(N2=1,"Just below limit; ","")&IF(O2=1,"Round amount; ","")&IF(P2=1,"No PO/GRN; ","")&IF(Q2=1,"Weekend payment; ","")) -> Near-duplicate;
A3: TXN-0002 | B3: V013 | C3: Riverside Facility Care Pvt Ltd | D3: INV-013-59054 | E3: 45750 | F3: 45770 | G3: 384561.13 | H3: PO495730 | I3: GR495730 | J3: AP-Mgr-04 | K3: =VALUE(LEFT(TEXT(G3,"0"),1)) -> 3 | L3: =IF(COUNTIFS($B$2:$B$1534,B3,$D$2:$D$1534,D3)>1,1,0) -> 0 | M3: =IF(AND(L3=0,COUNTIFS($B$2:$B$1534,B3,$G$2:$G$1534,G3,$E$2:$E$1534,">="&(E3-Assumptions!$B$5),$E$2:$E$1534,"<="&(E3+Assumptions!$B$5))>1),1,0) -> 0 | N3: =IF(AND(G3>=Assumptions!$B$4*(1-Assumptions!$B$6),G3<Assumptions!$B$4),1,0) -> 0 | O3: =IF(AND(G3>=Assumptions!$B$7,MOD(G3,Assumptions!$B$7)=0),1,0) -> 0 | P3: =IF(OR(H3="",I3=""),1,0) -> 0 | Q3: =IF(WEEKDAY(F3,2)>5,1,0) -> 0 | R3: =L3*Assumptions!$B$11+M3*Assumptions!$B$12+N3*Assumptions!$B$13+O3*Assumptions!$B$14+P3*Assumptions!$B$15+Q3*Assumptions!$B$16 -> 0 | S3: =IF(R3>=Assumptions!$B$20,"High",IF(R3>=Assumptions!$B$21,"Medium",IF(R3>=1,"Low","Clear"))) -> Clear | T3: =IF(R3=0,"",IF(L3=1,"Duplicate invoice; ","")&IF(M3=1,"Near-duplicate; ","")&IF(N3=1,"Just below limit; ","")&IF(O3=1,"Round amount; ","")&IF(P3=1,"No PO/GRN; ","")&IF(Q3=1,"Weekend payment; ",""))
A4: TXN-0003 | B4: V032 | C4: Jaywalk Maintenance Pvt Ltd | D4: INV-032-15856 | E4: 45749 | F4: 45772 | G4: 43914.9 | H4: PO408855 | I4: GR408855 | J4: AP-Mgr-04 | K4: =VALUE(LEFT(TEXT(G4,"0"),1)) -> 4 | L4: =IF(COUNTIFS($B$2:$B$1534,B4,$D$2:$D$1534,D4)>1,1,0) -> 0 | M4: =IF(AND(L4=0,COUNTIFS($B$2:$B$1534,B4,$G$2:$G$1534,G4,$E$2:$E$1534,">="&(E4-Assumptions!$B$5),$E$2:$E$1534,"<="&(E4+Assumptions!$B$5))>1),1,0) -> 0 | N4: =IF(AND(G4>=Assumptions!$B$4*(1-Assumptions!$B$6),G4<Assumptions!$B$4),1,0) -> 0 | O4: =IF(AND(G4>=Assumptions!$B$7,MOD(G4,Assumptions!$B$7)=0),1,0) -> 0 | P4: =IF(OR(H4="",I4=""),1,0) -> 0 | Q4: =IF(WEEKDAY(F4,2)>5,1,0) -> 0 | R4: =L4*Assumptions!$B$11+M4*Assumptions!$B$12+N4*Assumptions!$B$13+O4*Assumptions!$B$14+P4*Assumptions!$B$15+Q4*Assumptions!$B$16 -> 0 | S4: =IF(R4>=Assumptions!$B$20,"High",IF(R4>=Assumptions!$B$21,"Medium",IF(R4>=1,"Low","Clear"))) -> Clear | T4: =IF(R4=0,"",IF(L4=1,"Duplicate invoice; ","")&IF(M4=1,"Near-duplicate; ","")&IF(N4=1,"Just below limit; ","")&IF(O4=1,"Round amount; ","")&IF(P4=1,"No PO/GRN; ","")&IF(Q4=1,"Weekend payment; ",""))
A5: TXN-0004 | B5: V036 | C5: Vertex Facility Care Pvt Ltd | D5: INV-036-63903 | E5: 45753 | F5: 45775 | G5: 312657.25 | H5: PO401567 | I5: GR401567 | J5: AP-Mgr-01 | K5: =VALUE(LEFT(TEXT(G5,"0"),1)) -> 3 | L5: =IF(COUNTIFS($B$2:$B$1534,B5,$D$2:$D$1534,D5)>1,1,0) -> 0 | M5: =IF(AND(L5=0,COUNTIFS($B$2:$B$1534,B5,$G$2:$G$1534,G5,$E$2:$E$1534,">="&(E5-Assumptions!$B$5),$E$2:$E$1534,"<="&(E5+Assumptions!$B$5))>1),1,0) -> 0 | N5: =IF(AND(G5>=Assumptions!$B$4*(1-Assumptions!$B$6),G5<Assumptions!$B$4),1,0) -> 0 | O5: =IF(AND(G5>=Assumptions!$B$7,MOD(G5,Assumptions!$B$7)=0),1,0) -> 0 | P5: =IF(OR(H5="",I5=""),1,0) -> 0 | Q5: =IF(WEEKDAY(F5,2)>5,1,0) -> 0 | R5: =L5*Assumptions!$B$11+M5*Assumptions!$B$12+N5*Assumptions!$B$13+O5*Assumptions!$B$14+P5*Assumptions!$B$15+Q5*Assumptions!$B$16 -> 0 | S5: =IF(R5>=Assumptions!$B$20,"High",IF(R5>=Assumptions!$B$21,"Medium",IF(R5>=1,"Low","Clear"))) -> Clear | T5: =IF(R5=0,"",IF(L5=1,"Duplicate invoice; ","")&IF(M5=1,"Near-duplicate; ","")&IF(N5=1,"Just below limit; ","")&IF(O5=1,"Round amount; ","")&IF(P5=1,"No PO/GRN; ","")&IF(Q5=1,"Weekend payment; ",""))
A6: TXN-0005 | B6: V020 | C6: Fortis Stationery Pvt Ltd | D6: INV-020-22697 | E6: 45751 | F6: 45776 | G6: 281298.97 | H6: PO400206 | I6: GR400206 | J6: AP-Mgr-01 | K6: =VALUE(LEFT(TEXT(G6,"0"),1)) -> 2 | L6: =IF(COUNTIFS($B$2:$B$1534,B6,$D$2:$D$1534,D6)>1,1,0) -> 1 | M6: =IF(AND(L6=0,COUNTIFS($B$2:$B$1534,B6,$G$2:$G$1534,G6,$E$2:$E$1534,">="&(E6-Assumptions!$B$5),$E$2:$E$1534,"<="&(E6+Assumptions!$B$5))>1),1,0) -> 0 | N6: =IF(AND(G6>=Assumptions!$B$4*(1-Assumptions!$B$6),G6<Assumptions!$B$4),1,0) -> 0 | O6: =IF(AND(G6>=Assumptions!$B$7,MOD(G6,Assumptions!$B$7)=0),1,0) -> 0 | P6: =IF(OR(H6="",I6=""),1,0) -> 0 | Q6: =IF(WEEKDAY(F6,2)>5,1,0) -> 0 | R6: =L6*Assumptions!$B$11+M6*Assumptions!$B$12+N6*Assumptions!$B$13+O6*Assumptions!$B$14+P6*Assumptions!$B$15+Q6*Assumptions!$B$16 -> 5 | S6: =IF(R6>=Assumptions!$B$20,"High",IF(R6>=Assumptions!$B$21,"Medium",IF(R6>=1,"Low","Clear"))) -> High | T6: =IF(R6=0,"",IF(L6=1,"Duplicate invoice; ","")&IF(M6=1,"Near-duplicate; ","")&IF(N6=1,"Just below limit; ","")&IF(O6=1,"Round amount; ","")&IF(P6=1,"No PO/GRN; ","")&IF(Q6=1,"Weekend payment; ","")) -> Duplicate invoice;
A7: TXN-0006 | B7: V023 | C7: Greenfield Hardware Pvt Ltd | D7: INV-023-96159 | E7: 45751 | F7: 45776 | G7: 406994.11 | H7: PO474228 | I7: GR474228 | J7: AP-Mgr-04 | K7: =VALUE(LEFT(TEXT(G7,"0"),1)) -> 4 | L7: =IF(COUNTIFS($B$2:$B$1534,B7,$D$2:$D$1534,D7)>1,1,0) -> 0 | M7: =IF(AND(L7=0,COUNTIFS($B$2:$B$1534,B7,$G$2:$G$1534,G7,$E$2:$E$1534,">="&(E7-Assumptions!$B$5),$E$2:$E$1534,"<="&(E7+Assumptions!$B$5))>1),1,0) -> 0 | N7: =IF(AND(G7>=Assumptions!$B$4*(1-Assumptions!$B$6),G7<Assumptions!$B$4),1,0) -> 0 | O7: =IF(AND(G7>=Assumptions!$B$7,MOD(G7,Assumptions!$B$7)=0),1,0) -> 0 | P7: =IF(OR(H7="",I7=""),1,0) -> 0 | Q7: =IF(WEEKDAY(F7,2)>5,1,0) -> 0 | R7: =L7*Assumptions!$B$11+M7*Assumptions!$B$12+N7*Assumptions!$B$13+O7*Assumptions!$B$14+P7*Assumptions!$B$15+Q7*Assumptions!$B$16 -> 0 | S7: =IF(R7>=Assumptions!$B$20,"High",IF(R7>=Assumptions!$B$21,"Medium",IF(R7>=1,"Low","Clear"))) -> Clear | T7: =IF(R7=0,"",IF(L7=1,"Duplicate invoice; ","")&IF(M7=1,"Near-duplicate; ","")&IF(N7=1,"Just below limit; ","")&IF(O7=1,"Round amount; ","")&IF(P7=1,"No PO/GRN; ","")&IF(Q7=1,"Weekend payment; ",""))
A8: TXN-0007 | B8: V039 | C8: Ironwood Electricals Pvt Ltd | D8: INV-039-27038 | E8: 45749 | F8: 45777 | G8: 376026.44 | H8: PO418964 | I8: GR418964 | J8: AP-Mgr-05 | K8: =VALUE(LEFT(TEXT(G8,"0"),1)) -> 3 | L8: =IF(COUNTIFS($B$2:$B$1534,B8,$D$2:$D$1534,D8)>1,1,0) -> 0 | M8: =IF(AND(L8=0,COUNTIFS($B$2:$B$1534,B8,$G$2:$G$1534,G8,$E$2:$E$1534,">="&(E8-Assumptions!$B$5),$E$2:$E$1534,"<="&(E8+Assumptions!$B$5))>1),1,0) -> 0 | N8: =IF(AND(G8>=Assumptions!$B$4*(1-Assumptions!$B$6),G8<Assumptions!$B$4),1,0) -> 0 | O8: =IF(AND(G8>=Assumptions!$B$7,MOD(G8,Assumptions!$B$7)=0),1,0) -> 0 | P8: =IF(OR(H8="",I8=""),1,0) -> 0 | Q8: =IF(WEEKDAY(F8,2)>5,1,0) -> 0 | R8: =L8*Assumptions!$B$11+M8*Assumptions!$B$12+N8*Assumptions!$B$13+O8*Assumptions!$B$14+P8*Assumptions!$B$15+Q8*Assumptions!$B$16 -> 0 | S8: =IF(R8>=Assumptions!$B$20,"High",IF(R8>=Assumptions!$B$21,"Medium",IF(R8>=1,"Low","Clear"))) -> Clear | T8: =IF(R8=0,"",IF(L8=1,"Duplicate invoice; ","")&IF(M8=1,"Near-duplicate; ","")&IF(N8=1,"Just below limit; ","")&IF(O8=1,"Round amount; ","")&IF(P8=1,"No PO/GRN; ","")&IF(Q8=1,"Weekend payment; ",""))
A9: TXN-0008 | B9: V018 | C9: Ironwood Hardware Pvt Ltd | D9: INV-018-86011 | E9: 45749 | F9: 45778 | G9: 150713.77 | H9: PO476931 | I9: GR476931 | J9: AP-Mgr-06 | K9: =VALUE(LEFT(TEXT(G9,"0"),1)) -> 1 | L9: =IF(COUNTIFS($B$2:$B$1534,B9,$D$2:$D$1534,D9)>1,1,0) -> 0 | M9: =IF(AND(L9=0,COUNTIFS($B$2:$B$1534,B9,$G$2:$G$1534,G9,$E$2:$E$1534,">="&(E9-Assumptions!$B$5),$E$2:$E$1534,"<="&(E9+Assumptions!$B$5))>1),1,0) -> 0 | N9: =IF(AND(G9>=Assumptions!$B$4*(1-Assumptions!$B$6),G9<Assumptions!$B$4),1,0) -> 0 | O9: =IF(AND(G9>=Assumptions!$B$7,MOD(G9,Assumptions!$B$7)=0),1,0) -> 0 | P9: =IF(OR(H9="",I9=""),1,0) -> 0 | Q9: =IF(WEEKDAY(F9,2)>5,1,0) -> 0 | R9: =L9*Assumptions!$B$11+M9*Assumptions!$B$12+N9*Assumptions!$B$13+O9*Assumptions!$B$14+P9*Assumptions!$B$15+Q9*Assumptions!$B$16 -> 0 | S9: =IF(R9>=Assumptions!$B$20,"High",IF(R9>=Assumptions!$B$21,"Medium",IF(R9>=1,"Low","Clear"))) -> Clear | T9: =IF(R9=0,"",IF(L9=1,"Duplicate invoice; ","")&IF(M9=1,"Near-duplicate; ","")&IF(N9=1,"Just below limit; ","")&IF(O9=1,"Round amount; ","")&IF(P9=1,"No PO/GRN; ","")&IF(Q9=1,"Weekend payment; ",""))
A10: TXN-0009 | B10: V033 | C10: Unity Catering Pvt Ltd | D10: INV-033-94852 | E10: 45758 | F10: 45778 | G10: 26441.84 | H10: PO417342 | I10: GR417342 | J10: AP-Mgr-02 | K10: =VALUE(LEFT(TEXT(G10,"0"),1)) -> 2 | L10: =IF(COUNTIFS($B$2:$B$1534,B10,$D$2:$D$1534,D10)>1,1,0) -> 0 | M10: =IF(AND(L10=0,COUNTIFS($B$2:$B$1534,B10,$G$2:$G$1534,G10,$E$2:$E$1534,">="&(E10-Assumptions!$B$5),$E$2:$E$1534,"<="&(E10+Assumptions!$B$5))>1),1,0) -> 0 | N10: =IF(AND(G10>=Assumptions!$B$4*(1-Assumptions!$B$6),G10<Assumptions!$B$4),1,0) -> 0 | O10: =IF(AND(G10>=Assumptions!$B$7,MOD(G10,Assumptions!$B$7)=0),1,0) -> 0 | P10: =IF(OR(H10="",I10=""),1,0) -> 0 | Q10: =IF(WEEKDAY(F10,2)>5,1,0) -> 0 | R10: =L10*Assumptions!$B$11+M10*Assumptions!$B$12+N10*Assumptions!$B$13+O10*Assumptions!$B$14+P10*Assumptions!$B$15+Q10*Assumptions!$B$16 -> 0 | S10: =IF(R10>=Assumptions!$B$20,"High",IF(R10>=Assumptions!$B$21,"Medium",IF(R10>=1,"Low","Clear"))) -> Clear | T10: =IF(R10=0,"",IF(L10=1,"Duplicate invoice; ","")&IF(M10=1,"Near-duplicate; ","")&IF(N10=1,"Just below limit; ","")&IF(O10=1,"Round amount; ","")&IF(P10=1,"No PO/GRN; ","")&IF(Q10=1,"Weekend payment; ",""))
A11: TXN-0010 | B11: V037 | C11: Jaywalk Logistics Pvt Ltd | D11: INV-037-23954 | E11: 45750 | F11: 45778 | G11: 3350.46 | H11: PO466353 | I11: GR466353 | J11: AP-Mgr-05 | K11: =VALUE(LEFT(TEXT(G11,"0"),1)) -> 3 | L11: =IF(COUNTIFS($B$2:$B$1534,B11,$D$2:$D$1534,D11)>1,1,0) -> 0 | M11: =IF(AND(L11=0,COUNTIFS($B$2:$B$1534,B11,$G$2:$G$1534,G11,$E$2:$E$1534,">="&(E11-Assumptions!$B$5),$E$2:$E$1534,"<="&(E11+Assumptions!$B$5))>1),1,0) -> 0 | N11: =IF(AND(G11>=Assumptions!$B$4*(1-Assumptions!$B$6),G11<Assumptions!$B$4),1,0) -> 0 | O11: =IF(AND(G11>=Assumptions!$B$7,MOD(G11,Assumptions!$B$7)=0),1,0) -> 0 | P11: =IF(OR(H11="",I11=""),1,0) -> 0 | Q11: =IF(WEEKDAY(F11,2)>5,1,0) -> 0 | R11: =L11*Assumptions!$B$11+M11*Assumptions!$B$12+N11*Assumptions!$B$13+O11*Assumptions!$B$14+P11*Assumptions!$B$15+Q11*Assumptions!$B$16 -> 0 | S11: =IF(R11>=Assumptions!$B$20,"High",IF(R11>=Assumptions!$B$21,"Medium",IF(R11>=1,"Low","Clear"))) -> Clear | T11: =IF(R11=0,"",IF(L11=1,"Duplicate invoice; ","")&IF(M11=1,"Near-duplicate; ","")&IF(N11=1,"Just below limit; ","")&IF(O11=1,"Round amount; ","")&IF(P11=1,"No PO/GRN; ","")&IF(Q11=1,"Weekend payment; ",""))
A12: TXN-0011 | B12: V039 | C12: Ironwood Electricals Pvt Ltd | D12: INV-039-91233 | E12: 45751 | F12: 45778 | G12: 443101.88 | H12: PO436452 | I12: GR436452 | J12: AP-Mgr-06 | K12: =VALUE(LEFT(TEXT(G12,"0"),1)) -> 4 | L12: =IF(COUNTIFS($B$2:$B$1534,B12,$D$2:$D$1534,D12)>1,1,0) -> 0 | M12: =IF(AND(L12=0,COUNTIFS($B$2:$B$1534,B12,$G$2:$G$1534,G12,$E$2:$E$1534,">="&(E12-Assumptions!$B$5),$E$2:$E$1534,"<="&(E12+Assumptions!$B$5))>1),1,0) -> 0 | N12: =IF(AND(G12>=Assumptions!$B$4*(1-Assumptions!$B$6),G12<Assumptions!$B$4),1,0) -> 0 | O12: =IF(AND(G12>=Assumptions!$B$7,MOD(G12,Assumptions!$B$7)=0),1,0) -> 0 | P12: =IF(OR(H12="",I12=""),1,0) -> 0 | Q12: =IF(WEEKDAY(F12,2)>5,1,0) -> 0 | R12: =L12*Assumptions!$B$11+M12*Assumptions!$B$12+N12*Assumptions!$B$13+O12*Assumptions!$B$14+P12*Assumptions!$B$15+Q12*Assumptions!$B$16 -> 0 | S12: =IF(R12>=Assumptions!$B$20,"High",IF(R12>=Assumptions!$B$21,"Medium",IF(R12>=1,"Low","Clear"))) -> Clear | T12: =IF(R12=0,"",IF(L12=1,"Duplicate invoice; ","")&IF(M12=1,"Near-duplicate; ","")&IF(N12=1,"Just below limit; ","")&IF(O12=1,"Round amount; ","")&IF(P12=1,"No PO/GRN; ","")&IF(Q12=1,"Weekend payment; ",""))
A13: TXN-0012 | B13: V029 | C13: Orbit Travel Desk Pvt Ltd | D13: INV-029-47487 | E13: 45753 | F13: 45779 | G13: 356207.38 | H13: PO467915 | I13: GR467915 | J13: AP-Mgr-02 | K13: =VALUE(LEFT(TEXT(G13,"0"),1)) -> 3 | L13: =IF(COUNTIFS($B$2:$B$1534,B13,$D$2:$D$1534,D13)>1,1,0) -> 0 | M13: =IF(AND(L13=0,COUNTIFS($B$2:$B$1534,B13,$G$2:$G$1534,G13,$E$2:$E$1534,">="&(E13-Assumptions!$B$5),$E$2:$E$1534,"<="&(E13+Assumptions!$B$5))>1),1,0) -> 0 | N13: =IF(AND(G13>=Assumptions!$B$4*(1-Assumptions!$B$6),G13<Assumptions!$B$4),1,0) -> 0 | O13: =IF(AND(G13>=Assumptions!$B$7,MOD(G13,Assumptions!$B$7)=0),1,0) -> 0 | P13: =IF(OR(H13="",I13=""),1,0) -> 0 | Q13: =IF(WEEKDAY(F13,2)>5,1,0) -> 0 | R13: =L13*Assumptions!$B$11+M13*Assumptions!$B$12+N13*Assumptions!$B$13+O13*Assumptions!$B$14+P13*Assumptions!$B$15+Q13*Assumptions!$B$16 -> 0 | S13: =IF(R13>=Assumptions!$B$20,"High",IF(R13>=Assumptions!$B$21,"Medium",IF(R13>=1,"Low","Clear"))) -> Clear | T13: =IF(R13=0,"",IF(L13=1,"Duplicate invoice; ","")&IF(M13=1,"Near-duplicate; ","")&IF(N13=1,"Just below limit; ","")&IF(O13=1,"Round amount; ","")&IF(P13=1,"No PO/GRN; ","")&IF(Q13=1,"Weekend payment; ",""))
... A72: TXN-0071 | B72: V023 | C72: Greenfield Hardware Pvt Ltd | D72: INV-023-21253 | E72: 45760 | F72: 45796 | G72: 2058.96 | H72: PO454522 | I72: GR454522 | J72: AP-Mgr-01 | K72: =VALUE(LEFT(TEXT(G72,"0"),1)) -> 2 | L72: =IF(COUNTIFS($B$2:$B$1534,B72,$D$2:$D$1534,D72)>1,1,0) -> 0 | M72: =IF(AND(L72=0,COUNTIFS($B$2:$B$1534,B72,$G$2:$G$1534,G72,$E$2:$E$1534,">="&(E72-Assumptions!$B$5),$E$2:$E$1534,"<="&(E72+Assumptions!$B$5))>1),1,0) -> 0 | N72: =IF(AND(G72>=Assumptions!$B$4*(1-Assumptions!$B$6),G72<Assumptions!$B$4),1,0) -> 0 | O72: =IF(AND(G72>=Assumptions!$B$7,MOD(G72,Assumptions!$B$7)=0),1,0) -> 0 | P72: =IF(OR(H72="",I72=""),1,0) -> 0 | Q72: =IF(WEEKDAY(F72,2)>5,1,0) -> 0 | R72: =L72*Assumptions!$B$11+M72*Assumptions!$B$12+N72*Assumptions!$B$13+O72*Assumptions!$B$14+P72*Assumptions!$B$15+Q72*Assumptions!$B$16 -> 0 | S72: =IF(R72>=Assumptions!$B$20,"High",IF(R72>=Assumptions!$B$21,"Medium",IF(R72>=1,"Low","Clear"))) -> Clear | T72: =IF(R72=0,"",IF(L72=1,"Duplicate invoice; ","")&IF(M72=1,"Near-duplicate; ","")&IF(N72=1,"Just below limit; ","")&IF(O72=1,"Round amount; ","")&IF(P72=1,"No PO/GRN; ","")&IF(Q72=1,"Weekend payment; ",""))
A73: TXN-0072 | B73: V030 | C73: Delta Print Media Pvt Ltd | D73: INV-030-15492 | E73: 45766 | F73: 45796 | G73: 4025.07 | H73: PO426144 | J73: AP-Mgr-03 | K73: =VALUE(LEFT(TEXT(G73,"0"),1)) -> 4 | L73: =IF(COUNTIFS($B$2:$B$1534,B73,$D$2:$D$1534,D73)>1,1,0) -> 0 | M73: =IF(AND(L73=0,COUNTIFS($B$2:$B$1534,B73,$G$2:$G$1534,G73,$E$2:$E$1534,">="&(E73-Assumptions!$B$5),$E$2:$E$1534,"<="&(E73+Assumptions!$B$5))>1),1,0) -> 0 | N73: =IF(AND(G73>=Assumptions!$B$4*(1-Assumptions!$B$6),G73<Assumptions!$B$4),1,0) -> 0 | O73: =IF(AND(G73>=Assumptions!$B$7,MOD(G73,Assumptions!$B$7)=0),1,0) -> 0 | P73: =IF(OR(H73="",I73=""),1,0) -> 1 | Q73: =IF(WEEKDAY(F73,2)>5,1,0) -> 0 | R73: =L73*Assumptions!$B$11+M73*Assumptions!$B$12+N73*Assumptions!$B$13+O73*Assumptions!$B$14+P73*Assumptions!$B$15+Q73*Assumptions!$B$16 -> 4 | S73: =IF(R73>=Assumptions!$B$20,"High",IF(R73>=Assumptions!$B$21,"Medium",IF(R73>=1,"Low","Clear"))) -> Medium | T73: =IF(R73=0,"",IF(L73=1,"Duplicate invoice; ","")&IF(M73=1,"Near-duplicate; ","")&IF(N73=1,"Just below limit; ","")&IF(O73=1,"Round amount; ","")&IF(P73=1,"No PO/GRN; ","")&IF(Q73=1,"Weekend payment; ","")) -> No PO/GRN;
A74: TXN-0073 | B74: V035 | C74: Crestline Office Supplies Pvt Ltd | D74: INV-035-90754 | E74: 45764 | F74: 45796 | G74: 276744.28 | H74: PO413432 | I74: GR413432 | J74: AP-Mgr-06 | K74: =VALUE(LEFT(TEXT(G74,"0"),1)) -> 2 | L74: =IF(COUNTIFS($B$2:$B$1534,B74,$D$2:$D$1534,D74)>1,1,0) -> 0 | M74: =IF(AND(L74=0,COUNTIFS($B$2:$B$1534,B74,$G$2:$G$1534,G74,$E$2:$E$1534,">="&(E74-Assumptions!$B$5),$E$2:$E$1534,"<="&(E74+Assumptions!$B$5))>1),1,0) -> 0 | N74: =IF(AND(G74>=Assumptions!$B$4*(1-Assumptions!$B$6),G74<Assumptions!$B$4),1,0) -> 0 | O74: =IF(AND(G74>=Assumptions!$B$7,MOD(G74,Assumptions!$B$7)=0),1,0) -> 0 | P74: =IF(OR(H74="",I74=""),1,0) -> 0 | Q74: =IF(WEEKDAY(F74,2)>5,1,0) -> 0 | R74: =L74*Assumptions!$B$11+M74*Assumptions!$B$12+N74*Assumptions!$B$13+O74*Assumptions!$B$14+P74*Assumptions!$B$15+Q74*Assumptions!$B$16 -> 0 | S74: =IF(R74>=Assumptions!$B$20,"High",IF(R74>=Assumptions!$B$21,"Medium",IF(R74>=1,"Low","Clear"))) -> Clear | T74: =IF(R74=0,"",IF(L74=1,"Duplicate invoice; ","")&IF(M74=1,"Near-duplicate; ","")&IF(N74=1,"Just below limit; ","")&IF(O74=1,"Round amount; ","")&IF(P74=1,"No PO/GRN; ","")&IF(Q74=1,"Weekend payment; ",""))
A75: TXN-0074 | B75: V039 | C75: Ironwood Electricals Pvt Ltd | D75: INV-039-29441 | E75: 45768 | F75: 45796 | G75: 321939.49 | H75: PO442964 | I75: GR442964 | J75: AP-Mgr-01 | K75: =VALUE(LEFT(TEXT(G75,"0"),1)) -> 3 | L75: =IF(COUNTIFS($B$2:$B$1534,B75,$D$2:$D$1534,D75)>1,1,0) -> 0 | M75: =IF(AND(L75=0,COUNTIFS($B$2:$B$1534,B75,$G$2:$G$1534,G75,$E$2:$E$1534,">="&(E75-Assumptions!$B$5),$E$2:$E$1534,"<="&(E75+Assumptions!$B$5))>1),1,0) -> 0 | N75: =IF(AND(G75>=Assumptions!$B$4*(1-Assumptions!$B$6),G75<Assumptions!$B$4),1,0) -> 0 | O75: =IF(AND(G75>=Assumptions!$B$7,MOD(G75,Assumptions!$B$7)=0),1,0) -> 0 | P75: =IF(OR(H75="",I75=""),1,0) -> 0 | Q75: =IF(WEEKDAY(F75,2)>5,1,0) -> 0 | R75: =L75*Assumptions!$B$11+M75*Assumptions!$B$12+N75*Assumptions!$B$13+O75*Assumptions!$B$14+P75*Assumptions!$B$15+Q75*Assumptions!$B$16 -> 0 | S75: =IF(R75>=Assumptions!$B$20,"High",IF(R75>=Assumptions!$B$21,"Medium",IF(R75>=1,"Low","Clear"))) -> Clear | T75: =IF(R75=0,"",IF(L75=1,"Duplicate invoice; ","")&IF(M75=1,"Near-duplicate; ","")&IF(N75=1,"Just below limit; ","")&IF(O75=1,"Round amount; ","")&IF(P75=1,"No PO/GRN; ","")&IF(Q75=1,"Weekend payment; ",""))
A76: TXN-0075 | B76: V040 | C76: Unity Maintenance Pvt Ltd | D76: INV-040-65576 | E76: 45773 | F76: 45796 | G76: 6551.01 | J76: AP-Mgr-04 | K76: =VALUE(LEFT(TEXT(G76,"0"),1)) -> 6 | L76: =IF(COUNTIFS($B$2:$B$1534,B76,$D$2:$D$1534,D76)>1,1,0) -> 0 | M76: =IF(AND(L76=0,COUNTIFS($B$2:$B$1534,B76,$G$2:$G$1534,G76,$E$2:$E$1534,">="&(E76-Assumptions!$B$5),$E$2:$E$1534,"<="&(E76+Assumptions!$B$5))>1),1,0) -> 0 | N76: =IF(AND(G76>=Assumptions!$B$4*(1-Assumptions!$B$6),G76<Assumptions!$B$4),1,0) -> 0 | O76: =IF(AND(G76>=Assumptions!$B$7,MOD(G76,Assumptions!$B$7)=0),1,0) -> 0 | P76: =IF(OR(H76="",I76=""),1,0) -> 1 | Q76: =IF(WEEKDAY(F76,2)>5,1,0) -> 0 | R76: =L76*Assumptions!$B$11+M76*Assumptions!$B$12+N76*Assumptions!$B$13+O76*Assumptions!$B$14+P76*Assumptions!$B$15+Q76*Assumptions!$B$16 -> 4 | S76: =IF(R76>=Assumptions!$B$20,"High",IF(R76>=Assumptions!$B$21,"Medium",IF(R76>=1,"Low","Clear"))) -> Medium | T76: =IF(R76=0,"",IF(L76=1,"Duplicate invoice; ","")&IF(M76=1,"Near-duplicate; ","")&IF(N76=1,"Just below limit; ","")&IF(O76=1,"Round amount; ","")&IF(P76=1,"No PO/GRN; ","")&IF(Q76=1,"Weekend payment; ","")) -> No PO/GRN;
A77: TXN-0076 | B77: V007 | C77: Riverside Logistics Pvt Ltd | D77: INV-007-87664 | E77: 45762 | F77: 45797 | G77: 19762.73 | H77: PO403148 | I77: GR403148 | J77: AP-Mgr-06 | K77: =VALUE(LEFT(TEXT(G77,"0"),1)) -> 1 | L77: =IF(COUNTIFS($B$2:$B$1534,B77,$D$2:$D$1534,D77)>1,1,0) -> 0 | M77: =IF(AND(L77=0,COUNTIFS($B$2:$B$1534,B77,$G$2:$G$1534,G77,$E$2:$E$1534,">="&(E77-Assumptions!$B$5),$E$2:$E$1534,"<="&(E77+Assumptions!$B$5))>1),1,0) -> 0 | N77: =IF(AND(G77>=Assumptions!$B$4*(1-Assumptions!$B$6),G77<Assumptions!$B$4),1,0) -> 0 | O77: =IF(AND(G77>=Assumptions!$B$7,MOD(G77,Assumptions!$B$7)=0),1,0) -> 0 | P77: =IF(OR(H77="",I77=""),1,0) -> 0 | Q77: =IF(WEEKDAY(F77,2)>5,1,0) -> 0 | R77: =L77*Assumptions!$B$11+M77*Assumptions!$B$12+N77*Assumptions!$B$13+O77*Assumptions!$B$14+P77*Assumptions!$B$15+Q77*Assumptions!$B$16 -> 0 | S77: =IF(R77>=Assumptions!$B$20,"High",IF(R77>=Assumptions!$B$21,"Medium",IF(R77>=1,"Low","Clear"))) -> Clear | T77: =IF(R77=0,"",IF(L77=1,"Duplicate invoice; ","")&IF(M77=1,"Near-duplicate; ","")&IF(N77=1,"Just below limit; ","")&IF(O77=1,"Round amount; ","")&IF(P77=1,"No PO/GRN; ","")&IF(Q77=1,"Weekend payment; ",""))
A78: TXN-0077 | B78: V029 | C78: Orbit Travel Desk Pvt Ltd | D78: INV-029-30446 | E78: 45770 | F78: 45797 | G78: 3972.42 | H78: PO448997 | I78: GR448997 | J78: AP-Mgr-06 | K78: =VALUE(LEFT(TEXT(G78,"0"),1)) -> 3 | L78: =IF(COUNTIFS($B$2:$B$1534,B78,$D$2:$D$1534,D78)>1,1,0) -> 0 | M78: =IF(AND(L78=0,COUNTIFS($B$2:$B$1534,B78,$G$2:$G$1534,G78,$E$2:$E$1534,">="&(E78-Assumptions!$B$5),$E$2:$E$1534,"<="&(E78+Assumptions!$B$5))>1),1,0) -> 0 | N78: =IF(AND(G78>=Assumptions!$B$4*(1-Assumptions!$B$6),G78<Assumptions!$B$4),1,0) -> 0 | O78: =IF(AND(G78>=Assumptions!$B$7,MOD(G78,Assumptions!$B$7)=0),1,0) -> 0 | P78: =IF(OR(H78="",I78=""),1,0) -> 0 | Q78: =IF(WEEKDAY(F78,2)>5,1,0) -> 0 | R78: =L78*Assumptions!$B$11+M78*Assumptions!$B$12+N78*Assumptions!$B$13+O78*Assumptions!$B$14+P78*Assumptions!$B$15+Q78*Assumptions!$B$16 -> 0 | S78: =IF(R78>=Assumptions!$B$20,"High",IF(R78>=Assumptions!$B$21,"Medium",IF(R78>=1,"Low","Clear"))) -> Clear | T78: =IF(R78=0,"",IF(L78=1,"Duplicate invoice; ","")&IF(M78=1,"Near-duplicate; ","")&IF(N78=1,"Just below limit; ","")&IF(O78=1,"Round amount; ","")&IF(P78=1,"No PO/GRN; ","")&IF(Q78=1,"Weekend payment; ",""))
A79: TXN-0078 | B79: V034 | C79: Greenfield Stationery Pvt Ltd | D79: INV-034-27176 | E79: 45767 | F79: 45797 | G79: 425773.2 | H79: PO481006 | I79: GR481006 | J79: AP-Mgr-05 | K79: =VALUE(LEFT(TEXT(G79,"0"),1)) -> 4 | L79: =IF(COUNTIFS($B$2:$B$1534,B79,$D$2:$D$1534,D79)>1,1,0) -> 0 | M79: =IF(AND(L79=0,COUNTIFS($B$2:$B$1534,B79,$G$2:$G$1534,G79,$E$2:$E$1534,">="&(E79-Assumptions!$B$5),$E$2:$E$1534,"<="&(E79+Assumptions!$B$5))>1),1,0) -> 0 | N79: =IF(AND(G79>=Assumptions!$B$4*(1-Assumptions!$B$6),G79<Assumptions!$B$4),1,0) -> 0 | O79: =IF(AND(G79>=Assumptions!$B$7,MOD(G79,Assumptions!$B$7)=0),1,0) -> 0 | P79: =IF(OR(H79="",I79=""),1,0) -> 0 | Q79: =IF(WEEKDAY(F79,2)>5,1,0) -> 0 | R79: =L79*Assumptions!$B$11+M79*Assumptions!$B$12+N79*Assumptions!$B$13+O79*Assumptions!$B$14+P79*Assumptions!$B$15+Q79*Assumptions!$B$16 -> 0 | S79: =IF(R79>=Assumptions!$B$20,"High",IF(R79>=Assumptions!$B$21,"Medium",IF(R79>=1,"Low","Clear"))) -> Clear | T79: =IF(R79=0,"",IF(L79=1,"Duplicate invoice; ","")&IF(M79=1,"Near-duplicate; ","")&IF(N79=1,"Just below limit; ","")&IF(O79=1,"Round amount; ","")&IF(P79=1,"No PO/GRN; ","")&IF(Q79=1,"Weekend payment; ",""))
A80: TXN-0079 | B80: V012 | C80: Trident Office Supplies Pvt Ltd | D80: INV-012-47941 | E80: 45766 | F80: 45798 | G80: 231143.61 | H80: PO424420 | I80: GR424420 | J80: AP-Mgr-01 | K80: =VALUE(LEFT(TEXT(G80,"0"),1)) -> 2 | L80: =IF(COUNTIFS($B$2:$B$1534,B80,$D$2:$D$1534,D80)>1,1,0) -> 0 | M80: =IF(AND(L80=0,COUNTIFS($B$2:$B$1534,B80,$G$2:$G$1534,G80,$E$2:$E$1534,">="&(E80-Assumptions!$B$5),$E$2:$E$1534,"<="&(E80+Assumptions!$B$5))>1),1,0) -> 0 | N80: =IF(AND(G80>=Assumptions!$B$4*(1-Assumptions!$B$6),G80<Assumptions!$B$4),1,0) -> 0 | O80: =IF(AND(G80>=Assumptions!$B$7,MOD(G80,Assumptions!$B$7)=0),1,0) -> 0 | P80: =IF(OR(H80="",I80=""),1,0) -> 0 | Q80: =IF(WEEKDAY(F80,2)>5,1,0) -> 0 | R80: =L80*Assumptions!$B$11+M80*Assumptions!$B$12+N80*Assumptions!$B$13+O80*Assumptions!$B$14+P80*Assumptions!$B$15+Q80*Assumptions!$B$16 -> 0 | S80: =IF(R80>=Assumptions!$B$20,"High",IF(R80>=Assumptions!$B$21,"Medium",IF(R80>=1,"Low","Clear"))) -> Clear | T80: =IF(R80=0,"",IF(L80=1,"Duplicate invoice; ","")&IF(M80=1,"Near-duplicate; ","")&IF(N80=1,"Just below limit; ","")&IF(O80=1,"Round amount; ","")&IF(P80=1,"No PO/GRN; ","")&IF(Q80=1,"Weekend payment; ",""))
A81: TXN-0080 | B81: V019 | C81: Apex Hardware Pvt Ltd | D81: INV-019-55398 | E81: 45769 | F81: 45798 | G81: 734414.35 | H81: PO410358 | I81: GR410358 | J81: AP-Mgr-04 | K81: =VALUE(LEFT(TEXT(G81,"0"),1)) -> 7 | L81: =IF(COUNTIFS($B$2:$B$1534,B81,$D$2:$D$1534,D81)>1,1,0) -> 0 | M81: =IF(AND(L81=0,COUNTIFS($B$2:$B$1534,B81,$G$2:$G$1534,G81,$E$2:$E$1534,">="&(E81-Assumptions!$B$5),$E$2:$E$1534,"<="&(E81+Assumptions!$B$5))>1),1,0) -> 0 | N81: =IF(AND(G81>=Assumptions!$B$4*(1-Assumptions!$B$6),G81<Assumptions!$B$4),1,0) -> 0 | O81: =IF(AND(G81>=Assumptions!$B$7,MOD(G81,Assumptions!$B$7)=0),1,0) -> 0 | P81: =IF(OR(H81="",I81=""),1,0) -> 0 | Q81: =IF(WEEKDAY(F81,2)>5,1,0) -> 0 | R81: =L81*Assumptions!$B$11+M81*Assumptions!$B$12+N81*Assumptions!$B$13+O81*Assumptions!$B$14+P81*Assumptions!$B$15+Q81*Assumptions!$B$16 -> 0 | S81: =IF(R81>=Assumptions!$B$20,"High",IF(R81>=Assumptions!$B$21,"Medium",IF(R81>=1,"Low","Clear"))) -> Clear | T81: =IF(R81=0,"",IF(L81=1,"Duplicate invoice; ","")&IF(M81=1,"Near-duplicate; ","")&IF(N81=1,"Just below limit; ","")&IF(O81=1,"Round amount; ","")&IF(P81=1,"No PO/GRN; ","")&IF(Q81=1,"Weekend payment; ",""))
A82: TXN-0081 | B82: V001 | C82: Unity Logistics Pvt Ltd | D82: INV-001-53231 | E82: 45767 | F82: 45799 | G82: 6299.55 | H82: PO491757 | I82: GR491757 | J82: AP-Mgr-04 | K82: =VALUE(LEFT(TEXT(G82,"0"),1)) -> 6 | L82: =IF(COUNTIFS($B$2:$B$1534,B82,$D$2:$D$1534,D82)>1,1,0) -> 0 | M82: =IF(AND(L82=0,COUNTIFS($B$2:$B$1534,B82,$G$2:$G$1534,G82,$E$2:$E$1534,">="&(E82-Assumptions!$B$5),$E$2:$E$1534,"<="&(E82+Assumptions!$B$5))>1),1,0) -> 0 | N82: =IF(AND(G82>=Assumptions!$B$4*(1-Assumptions!$B$6),G82<Assumptions!$B$4),1,0) -> 0 | O82: =IF(AND(G82>=Assumptions!$B$7,MOD(G82,Assumptions!$B$7)=0),1,0) -> 0 | P82: =IF(OR(H82="",I82=""),1,0) -> 0 | Q82: =IF(WEEKDAY(F82,2)>5,1,0) -> 0 | R82: =L82*Assumptions!$B$11+M82*Assumptions!$B$12+N82*Assumptions!$B$13+O82*Assumptions!$B$14+P82*Assumptions!$B$15+Q82*Assumptions!$B$16 -> 0 | S82: =IF(R82>=Assumptions!$B$20,"High",IF(R82>=Assumptions!$B$21,"Medium",IF(R82>=1,"Low","Clear"))) -> Clear | T82: =IF(R82=0,"",IF(L82=1,"Duplicate invoice; ","")&IF(M82=1,"Near-duplicate; ","")&IF(N82=1,"Just below limit; ","")&IF(O82=1,"Round amount; ","")&IF(P82=1,"No PO/GRN; ","")&IF(Q82=1,"Weekend payment; ",""))
A83: TXN-0082 | B83: V031 | C83: Crestline Travel Desk Pvt Ltd | D83: INV-031-52992 | E83: 45760 | F83: 45799 | G83: 449473.96 | H83: PO473584 | I83: GR473584 | J83: AP-Mgr-05 | K83: =VALUE(LEFT(TEXT(G83,"0"),1)) -> 4 | L83: =IF(COUNTIFS($B$2:$B$1534,B83,$D$2:$D$1534,D83)>1,1,0) -> 0 | M83: =IF(AND(L83=0,COUNTIFS($B$2:$B$1534,B83,$G$2:$G$1534,G83,$E$2:$E$1534,">="&(E83-Assumptions!$B$5),$E$2:$E$1534,"<="&(E83+Assumptions!$B$5))>1),1,0) -> 0 | N83: =IF(AND(G83>=Assumptions!$B$4*(1-Assumptions!$B$6),G83<Assumptions!$B$4),1,0) -> 0 | O83: =IF(AND(G83>=Assumptions!$B$7,MOD(G83,Assumptions!$B$7)=0),1,0) -> 0 | P83: =IF(OR(H83="",I83=""),1,0) -> 0 | Q83: =IF(WEEKDAY(F83,2)>5,1,0) -> 0 | R83: =L83*Assumptions!$B$11+M83*Assumptions!$B$12+N83*Assumptions!$B$13+O83*Assumptions!$B$14+P83*Assumptions!$B$15+Q83*Assumptions!$B$16 -> 0 | S83: =IF(R83>=Assumptions!$B$20,"High",IF(R83>=Assumptions!$B$21,"Medium",IF(R83>=1,"Low","Clear"))) -> Clear | T83: =IF(R83=0,"",IF(L83=1,"Duplicate invoice; ","")&IF(M83=1,"Near-duplicate; ","")&IF(N83=1,"Just below limit; ","")&IF(O83=1,"Round amount; ","")&IF(P83=1,"No PO/GRN; ","")&IF(Q83=1,"Weekend payment; ",""))
A84: TXN-0083 | B84: V036 | C84: Vertex Facility Care Pvt Ltd | D84: INV-036-71726 | E84: 45778 | F84: 45799 | G84: 9967.53 | H84: PO430781 | I84: GR430781 | J84: AP-Mgr-03 | K84: =VALUE(LEFT(TEXT(G84,"0"),1)) -> 9 | L84: =IF(COUNTIFS($B$2:$B$1534,B84,$D$2:$D$1534,D84)>1,1,0) -> 0 | M84: =IF(AND(L84=0,COUNTIFS($B$2:$B$1534,B84,$G$2:$G$1534,G84,$E$2:$E$1534,">="&(E84-Assumptions!$B$5),$E$2:$E$1534,"<="&(E84+Assumptions!$B$5))>1),1,0) -> 0 | N84: =IF(AND(G84>=Assumptions!$B$4*(1-Assumptions!$B$6),G84<Assumptions!$B$4),1,0) -> 0 | O84: =IF(AND(G84>=Assumptions!$B$7,MOD(G84,Assumptions!$B$7)=0),1,0) -> 0 | P84: =IF(OR(H84="",I84=""),1,0) -> 0 | Q84: =IF(WEEKDAY(F84,2)>5,1,0) -> 0 | R84: =L84*Assumptions!$B$11+M84*Assumptions!$B$12+N84*Assumptions!$B$13+O84*Assumptions!$B$14+P84*Assumptions!$B$15+Q84*Assumptions!$B$16 -> 0 | S84: =IF(R84>=Assumptions!$B$20,"High",IF(R84>=Assumptions!$B$21,"Medium",IF(R84>=1,"Low","Clear"))) -> Clear | T84: =IF(R84=0,"",IF(L84=1,"Duplicate invoice; ","")&IF(M84=1,"Near-duplicate; ","")&IF(N84=1,"Just below limit; ","")&IF(O84=1,"Round amount; ","")&IF(P84=1,"No PO/GRN; ","")&IF(Q84=1,"Weekend payment; ",""))
A85: TXN-0084 | B85: V012 | C85: Trident Office Supplies Pvt Ltd | D85: INV-012-84323 | E85: 45761 | F85: 45800 | G85: 70931.56 | H85: PO479377 | I85: GR479377 | J85: AP-Mgr-05 | K85: =VALUE(LEFT(TEXT(G85,"0"),1)) -> 7 | L85: =IF(COUNTIFS($B$2:$B$1534,B85,$D$2:$D$1534,D85)>1,1,0) -> 0 | M85: =IF(AND(L85=0,COUNTIFS($B$2:$B$1534,B85,$G$2:$G$1534,G85,$E$2:$E$1534,">="&(E85-Assumptions!$B$5),$E$2:$E$1534,"<="&(E85+Assumptions!$B$5))>1),1,0) -> 0 | N85: =IF(AND(G85>=Assumptions!$B$4*(1-Assumptions!$B$6),G85<Assumptions!$B$4),1,0) -> 0 | O85: =IF(AND(G85>=Assumptions!$B$7,MOD(G85,Assumptions!$B$7)=0),1,0) -> 0 | P85: =IF(OR(H85="",I85=""),1,0) -> 0 | Q85: =IF(WEEKDAY(F85,2)>5,1,0) -> 0 | R85: =L85*Assumptions!$B$11+M85*Assumptions!$B$12+N85*Assumptions!$B$13+O85*Assumptions!$B$14+P85*Assumptions!$B$15+Q85*Assumptions!$B$16 -> 0 | S85: =IF(R85>=Assumptions!$B$20,"High",IF(R85>=Assumptions!$B$21,"Medium",IF(R85>=1,"Low","Clear"))) -> Clear | T85: =IF(R85=0,"",IF(L85=1,"Duplicate invoice; ","")&IF(M85=1,"Near-duplicate; ","")&IF(N85=1,"Just below limit; ","")&IF(O85=1,"Round amount; ","")&IF(P85=1,"No PO/GRN; ","")&IF(Q85=1,"Weekend payment; ",""))
A86: TXN-0085 | B86: V029 | C86: Orbit Travel Desk Pvt Ltd | D86: INV-029-47752 | E86: 45774 | F86: 45800 | G86: 6326.58 | H86: PO417172 | I86: GR417172 | J86: AP-Mgr-04 | K86: =VALUE(LEFT(TEXT(G86,"0"),1)) -> 6 | L86: =IF(COUNTIFS($B$2:$B$1534,B86,$D$2:$D$1534,D86)>1,1,0) -> 0 | M86: =IF(AND(L86=0,COUNTIFS($B$2:$B$1534,B86,$G$2:$G$1534,G86,$E$2:$E$1534,">="&(E86-Assumptions!$B$5),$E$2:$E$1534,"<="&(E86+Assumptions!$B$5))>1),1,0) -> 0 | N86: =IF(AND(G86>=Assumptions!$B$4*(1-Assumptions!$B$6),G86<Assumptions!$B$4),1,0) -> 0 | O86: =IF(AND(G86>=Assumptions!$B$7,MOD(G86,Assumptions!$B$7)=0),1,0) -> 0 | P86: =IF(OR(H86="",I86=""),1,0) -> 0 | Q86: =IF(WEEKDAY(F86,2)>5,1,0) -> 0 | R86: =L86*Assumptions!$B$11+M86*Assumptions!$B$12+N86*Assumptions!$B$13+O86*Assumptions!$B$14+P86*Assumptions!$B$15+Q86*Assumptions!$B$16 -> 0 | S86: =IF(R86>=Assumptions!$B$20,"High",IF(R86>=Assumptions!$B$21,"Medium",IF(R86>=1,"Low","Clear"))) -> Clear | T86: =IF(R86=0,"",IF(L86=1,"Duplicate invoice; ","")&IF(M86=1,"Near-duplicate; ","")&IF(N86=1,"Just below limit; ","")&IF(O86=1,"Round amount; ","")&IF(P86=1,"No PO/GRN; ","")&IF(Q86=1,"Weekend payment; ",""))
A87: TXN-0086 | B87: V002 | C87: Apex Stationery Pvt Ltd | D87: INV-002-84000 | E87: 45773 | F87: 45803 | G87: 5379.06 | H87: PO416505 | I87: GR416505 | J87: AP-Mgr-02 | K87: =VALUE(LEFT(TEXT(G87,"0"),1)) -> 5 | L87: =IF(COUNTIFS($B$2:$B$1534,B87,$D$2:$D$1534,D87)>1,1,0) -> 0 | M87: =IF(AND(L87=0,COUNTIFS($B$2:$B$1534,B87,$G$2:$G$1534,G87,$E$2:$E$1534,">="&(E87-Assumptions!$B$5),$E$2:$E$1534,"<="&(E87+Assumptions!$B$5))>1),1,0) -> 0 | N87: =IF(AND(G87>=Assumptions!$B$4*(1-Assumptions!$B$6),G87<Assumptions!$B$4),1,0) -> 0 | O87: =IF(AND(G87>=Assumptions!$B$7,MOD(G87,Assumptions!$B$7)=0),1,0) -> 0 | P87: =IF(OR(H87="",I87=""),1,0) -> 0 | Q87: =IF(WEEKDAY(F87,2)>5,1,0) -> 0 | R87: =L87*Assumptions!$B$11+M87*Assumptions!$B$12+N87*Assumptions!$B$13+O87*Assumptions!$B$14+P87*Assumptions!$B$15+Q87*Assumptions!$B$16 -> 0 | S87: =IF(R87>=Assumptions!$B$20,"High",IF(R87>=Assumptions!$B$21,"Medium",IF(R87>=1,"Low","Clear"))) -> Clear | T87: =IF(R87=0,"",IF(L87=1,"Duplicate invoice; ","")&IF(M87=1,"Near-duplicate; ","")&IF(N87=1,"Just below limit; ","")&IF(O87=1,"Round amount; ","")&IF(P87=1,"No PO/GRN; ","")&IF(Q87=1,"Weekend payment; ",""))
A88: TXN-0087 | B88: V009 | C88: Bluepeak Office Supplies Pvt Ltd | D88: INV-009-67067 | E88: 45769 | F88: 45803 | G88: 1718.33 | H88: PO489538 | I88: GR489538 | J88: AP-Mgr-02 | K88: =VALUE(LEFT(TEXT(G88,"0"),1)) -> 1 | L88: =IF(COUNTIFS($B$2:$B$1534,B88,$D$2:$D$1534,D88)>1,1,0) -> 0 | M88: =IF(AND(L88=0,COUNTIFS($B$2:$B$1534,B88,$G$2:$G$1534,G88,$E$2:$E$1534,">="&(E88-Assumptions!$B$5),$E$2:$E$1534,"<="&(E88+Assumptions!$B$5))>1),1,0) -> 0 | N88: =IF(AND(G88>=Assumptions!$B$4*(1-Assumptions!$B$6),G88<Assumptions!$B$4),1,0) -> 0 | O88: =IF(AND(G88>=Assumptions!$B$7,MOD(G88,Assumptions!$B$7)=0),1,0) -> 0 | P88: =IF(OR(H88="",I88=""),1,0) -> 0 | Q88: =IF(WEEKDAY(F88,2)>5,1,0) -> 0 | R88: =L88*Assumptions!$B$11+M88*Assumptions!$B$12+N88*Assumptions!$B$13+O88*Assumptions!$B$14+P88*Assumptions!$B$15+Q88*Assumptions!$B$16 -> 0 | S88: =IF(R88>=Assumptions!$B$20,"High",IF(R88>=Assumptions!$B$21,"Medium",IF(R88>=1,"Low","Clear"))) -> Clear | T88: =IF(R88=0,"",IF(L88=1,"Duplicate invoice; ","")&IF(M88=1,"Near-duplicate; ","")&IF(N88=1,"Just below limit; ","")&IF(O88=1,"Round amount; ","")&IF(P88=1,"No PO/GRN; ","")&IF(Q88=1,"Weekend payment; ",""))
... A139: TXN-0138 | B139: V040 | C139: Unity Maintenance Pvt Ltd | D139: INV-040-37235 | E139: 45778 | F139: 45817 | G139: 759147.79 | H139: PO413006 | I139: GR413006 | J139: AP-Mgr-06 | K139: =VALUE(LEFT(TEXT(G139,"0"),1)) -> 7 | L139: =IF(COUNTIFS($B$2:$B$1534,B139,$D$2:$D$1534,D139)>1,1,0) -> 0 | M139: =IF(AND(L139=0,COUNTIFS($B$2:$B$1534,B139,$G$2:$G$1534,G139,$E$2:$E$1534,">="&(E139-Assumptions!$B$5),$E$2:$E$1534,"<="&(E139+Assumptions!$B$5))>1),1,0) -> 0 | N139: =IF(AND(G139>=Assumptions!$B$4*(1-Assumptions!$B$6),G139<Assumptions!$B$4),1,0) -> 0 | O139: =IF(AND(G139>=Assumptions!$B$7,MOD(G139,Assumptions!$B$7)=0),1,0) -> 0 | P139: =IF(OR(H139="",I139=""),1,0) -> 0 | Q139: =IF(WEEKDAY(F139,2)>5,1,0) -> 0 | R139: =L139*Assumptions!$B$11+M139*Assumptions!$B$12+N139*Assumptions!$B$13+O139*Assumptions!$B$14+P139*Assumptions!$B$15+Q139*Assumptions!$B$16 -> 0 | S139: =IF(R139>=Assumptions!$B$20,"High",IF(R139>=Assumptions!$B$21,"Medium",IF(R139>=1,"Low","Clear"))) -> Clear | T139: =IF(R139=0,"",IF(L139=1,"Duplicate invoice; ","")&IF(M139=1,"Near-duplicate; ","")&IF(N139=1,"Just below limit; ","")&IF(O139=1,"Round amount; ","")&IF(P139=1,"No PO/GRN; ","")&IF(Q139=1,"Weekend payment; ",""))
A140: TXN-0139 | B140: V004 | C140: Horizon IT Services Pvt Ltd | D140: INV-004-33590 | E140: 45783 | F140: 45818 | G140: 1245.1 | J140: AP-Mgr-02 | K140: =VALUE(LEFT(TEXT(G140,"0"),1)) -> 1 | L140: =IF(COUNTIFS($B$2:$B$1534,B140,$D$2:$D$1534,D140)>1,1,0) -> 0 | M140: =IF(AND(L140=0,COUNTIFS($B$2:$B$1534,B140,$G$2:$G$1534,G140,$E$2:$E$1534,">="&(E140-Assumptions!$B$5),$E$2:$E$1534,"<="&(E140+Assumptions!$B$5))>1),1,0) -> 0 | N140: =IF(AND(G140>=Assumptions!$B$4*(1-Assumptions!$B$6),G140<Assumptions!$B$4),1,0) -> 0 | O140: =IF(AND(G140>=Assumptions!$B$7,MOD(G140,Assumptions!$B$7)=0),1,0) -> 0 | P140: =IF(OR(H140="",I140=""),1,0) -> 1 | Q140: =IF(WEEKDAY(F140,2)>5,1,0) -> 0 | R140: =L140*Assumptions!$B$11+M140*Assumptions!$B$12+N140*Assumptions!$B$13+O140*Assumptions!$B$14+P140*Assumptions!$B$15+Q140*Assumptions!$B$16 -> 4 | S140: =IF(R140>=Assumptions!$B$20,"High",IF(R140>=Assumptions!$B$21,"Medium",IF(R140>=1,"Low","Clear"))) -> Medium | T140: =IF(R140=0,"",IF(L140=1,"Duplicate invoice; ","")&IF(M140=1,"Near-duplicate; ","")&IF(N140=1,"Just below limit; ","")&IF(O140=1,"Round amount; ","")&IF(P140=1,"No PO/GRN; ","")&IF(Q140=1,"Weekend payment; ","")) -> No PO/GRN;
A141: TXN-0140 | B141: V017 | C141: Orbit Catering Pvt Ltd | D141: INV-017-59666 | E141: 45799 | F141: 45819 | G141: 312131.22 | H141: PO417988 | I141: GR417988 | J141: AP-Mgr-06 | K141: =VALUE(LEFT(TEXT(G141,"0"),1)) -> 3 | L141: =IF(COUNTIFS($B$2:$B$1534,B141,$D$2:$D$1534,D141)>1,1,0) -> 0 | M141: =IF(AND(L141=0,COUNTIFS($B$2:$B$1534,B141,$G$2:$G$1534,G141,$E$2:$E$1534,">="&(E141-Assumptions!$B$5),$E$2:$E$1534,"<="&(E141+Assumptions!$B$5))>1),1,0) -> 0 | N141: =IF(AND(G141>=Assumptions!$B$4*(1-Assumptions!$B$6),G141<Assumptions!$B$4),1,0) -> 0 | O141: =IF(AND(G141>=Assumptions!$B$7,MOD(G141,Assumptions!$B$7)=0),1,0) -> 0 | P141: =IF(OR(H141="",I141=""),1,0) -> 0 | Q141: =IF(WEEKDAY(F141,2)>5,1,0) -> 0 | R141: =L141*Assumptions!$B$11+M141*Assumptions!$B$12+N141*Assumptions!$B$13+O141*Assumptions!$B$14+P141*Assumptions!$B$15+Q141*Assumptions!$B$16 -> 0 | S141: =IF(R141>=Assumptions!$B$20,"High",IF(R141>=Assumptions!$B$21,"Medium",IF(R141>=1,"Low","Clear"))) -> Clear | T141: =IF(R141=0,"",IF(L141=1,"Duplicate invoice; ","")&IF(M141=1,"Near-duplicate; ","")&IF(N141=1,"Just below limit; ","")&IF(O141=1,"Round amount; ","")&IF(P141=1,"No PO/GRN; ","")&IF(Q141=1,"Weekend payment; ",""))
A142: TXN-0141 | B142: V023 | C142: Greenfield Hardware Pvt Ltd | D142: INV-023-81650 | E142: 45790 | F142: 45819 | G142: 337139.91 | H142: PO467212 | I142: GR467212 | J142: AP-Mgr-06 | K142: =VALUE(LEFT(TEXT(G142,"0"),1)) -> 3 | L142: =IF(COUNTIFS($B$2:$B$1534,B142,$D$2:$D$1534,D142)>1,1,0) -> 0 | M142: =IF(AND(L142=0,COUNTIFS($B$2:$B$1534,B142,$G$2:$G$1534,G142,$E$2:$E$1534,">="&(E142-Assumptions!$B$5),$E$2:$E$1534,"<="&(E142+Assumptions!$B$5))>1),1,0) -> 0 | N142: =IF(AND(G142>=Assumptions!$B$4*(1-Assumptions!$B$6),G142<Assumptions!$B$4),1,0) -> 0 | O142: =IF(AND(G142>=Assumptions!$B$7,MOD(G142,Assumptions!$B$7)=0),1,0) -> 0 | P142: =IF(OR(H142="",I142=""),1,0) -> 0 | Q142: =IF(WEEKDAY(F142,2)>5,1,0) -> 0 | R142: =L142*Assumptions!$B$11+M142*Assumptions!$B$12+N142*Assumptions!$B$13+O142*Assumptions!$B$14+P142*Assumptions!$B$15+Q142*Assumptions!$B$16 -> 0 | S142: =IF(R142>=Assumptions!$B$20,"High",IF(R142>=Assumptions!$B$21,"Medium",IF(R142>=1,"Low","Clear"))) -> Clear | T142: =IF(R142=0,"",IF(L142=1,"Duplicate invoice; ","")&IF(M142=1,"Near-duplicate; ","")&IF(N142=1,"Just below limit; ","")&IF(O142=1,"Round amount; ","")&IF(P142=1,"No PO/GRN; ","")&IF(Q142=1,"Weekend payment; ",""))
A143: TXN-0142 | B143: V031 | C143: Crestline Travel Desk Pvt Ltd | D143: INV-031-38655 | E143: 45786 | F143: 45819 | G143: 2570.21 | H143: PO461506 | I143: GR461506 | J143: AP-Mgr-02 | K143: =VALUE(LEFT(TEXT(G143,"0"),1)) -> 2 | L143: =IF(COUNTIFS($B$2:$B$1534,B143,$D$2:$D$1534,D143)>1,1,0) -> 0 | M143: =IF(AND(L143=0,COUNTIFS($B$2:$B$1534,B143,$G$2:$G$1534,G143,$E$2:$E$1534,">="&(E143-Assumptions!$B$5),$E$2:$E$1534,"<="&(E143+Assumptions!$B$5))>1),1,0) -> 1 | N143: =IF(AND(G143>=Assumptions!$B$4*(1-Assumptions!$B$6),G143<Assumptions!$B$4),1,0) -> 0 | O143: =IF(AND(G143>=Assumptions!$B$7,MOD(G143,Assumptions!$B$7)=0),1,0) -> 0 | P143: =IF(OR(H143="",I143=""),1,0) -> 0 | Q143: =IF(WEEKDAY(F143,2)>5,1,0) -> 0 | R143: =L143*Assumptions!$B$11+M143*Assumptions!$B$12+N143*Assumptions!$B$13+O143*Assumptions!$B$14+P143*Assumptions!$B$15+Q143*Assumptions!$B$16 -> 3 | S143: =IF(R143>=Assumptions!$B$20,"High",IF(R143>=Assumptions!$B$21,"Medium",IF(R143>=1,"Low","Clear"))) -> Medium | T143: =IF(R143=0,"",IF(L143=1,"Duplicate invoice; ","")&IF(M143=1,"Near-duplicate; ","")&IF(N143=1,"Just below limit; ","")&IF(O143=1,"Round amount; ","")&IF(P143=1,"No PO/GRN; ","")&IF(Q143=1,"Weekend payment; ","")) -> Near-duplicate;
A144: TXN-0143 | B144: V004 | C144: Horizon IT Services Pvt Ltd | D144: INV-004-63347 | E144: 45790 | F144: 45820 | G144: 63796.85 | H144: PO408333 | I144: GR408333 | J144: AP-Mgr-03 | K144: =VALUE(LEFT(TEXT(G144,"0"),1)) -> 6 | L144: =IF(COUNTIFS($B$2:$B$1534,B144,$D$2:$D$1534,D144)>1,1,0) -> 0 | M144: =IF(AND(L144=0,COUNTIFS($B$2:$B$1534,B144,$G$2:$G$1534,G144,$E$2:$E$1534,">="&(E144-Assumptions!$B$5),$E$2:$E$1534,"<="&(E144+Assumptions!$B$5))>1),1,0) -> 0 | N144: =IF(AND(G144>=Assumptions!$B$4*(1-Assumptions!$B$6),G144<Assumptions!$B$4),1,0) -> 0 | O144: =IF(AND(G144>=Assumptions!$B$7,MOD(G144,Assumptions!$B$7)=0),1,0) -> 0 | P144: =IF(OR(H144="",I144=""),1,0) -> 0 | Q144: =IF(WEEKDAY(F144,2)>5,1,0) -> 0 | R144: =L144*Assumptions!$B$11+M144*Assumptions!$B$12+N144*Assumptions!$B$13+O144*Assumptions!$B$14+P144*Assumptions!$B$15+Q144*Assumptions!$B$16 -> 0 | S144: =IF(R144>=Assumptions!$B$20,"High",IF(R144>=Assumptions!$B$21,"Medium",IF(R144>=1,"Low","Clear"))) -> Clear | T144: =IF(R144=0,"",IF(L144=1,"Duplicate invoice; ","")&IF(M144=1,"Near-duplicate; ","")&IF(N144=1,"Just below limit; ","")&IF(O144=1,"Round amount; ","")&IF(P144=1,"No PO/GRN; ","")&IF(Q144=1,"Weekend payment; ",""))
A145: TXN-0144 | B145: V032 | C145: Jaywalk Maintenance Pvt Ltd | D145: INV-032-96474 | E145: 45783 | F145: 45820 | G145: 198382.47 | H145: PO416828 | I145: GR416828 | J145: AP-Mgr-04 | K145: =VALUE(LEFT(TEXT(G145,"0"),1)) -> 1 | L145: =IF(COUNTIFS($B$2:$B$1534,B145,$D$2:$D$1534,D145)>1,1,0) -> 0 | M145: =IF(AND(L145=0,COUNTIFS($B$2:$B$1534,B145,$G$2:$G$1534,G145,$E$2:$E$1534,">="&(E145-Assumptions!$B$5),$E$2:$E$1534,"<="&(E145+Assumptions!$B$5))>1),1,0) -> 0 | N145: =IF(AND(G145>=Assumptions!$B$4*(1-Assumptions!$B$6),G145<Assumptions!$B$4),1,0) -> 0 | O145: =IF(AND(G145>=Assumptions!$B$7,MOD(G145,Assumptions!$B$7)=0),1,0) -> 0 | P145: =IF(OR(H145="",I145=""),1,0) -> 0 | Q145: =IF(WEEKDAY(F145,2)>5,1,0) -> 0 | R145: =L145*Assumptions!$B$11+M145*Assumptions!$B$12+N145*Assumptions!$B$13+O145*Assumptions!$B$14+P145*Assumptions!$B$15+Q145*Assumptions!$B$16 -> 0 | S145: =IF(R145>=Assumptions!$B$20,"High",IF(R145>=Assumptions!$B$21,"Medium",IF(R145>=1,"Low","Clear"))) -> Clear | T145: =IF(R145=0,"",IF(L145=1,"Duplicate invoice; ","")&IF(M145=1,"Near-duplicate; ","")&IF(N145=1,"Just below limit; ","")&IF(O145=1,"Round amount; ","")&IF(P145=1,"No PO/GRN; ","")&IF(Q145=1,"Weekend payment; ",""))
A146: TXN-0145 | B146: V032 | C146: Jaywalk Maintenance Pvt Ltd | D146: INV-032-72746 | E146: 45800 | F146: 45820 | G146: 52746.38 | H146: PO461524 | I146: GR461524 | J146: AP-Mgr-04 | K146: =VALUE(LEFT(TEXT(G146,"0"),1)) -> 5 | L146: =IF(COUNTIFS($B$2:$B$1534,B146,$D$2:$D$1534,D146)>1,1,0) -> 0 | M146: =IF(AND(L146=0,COUNTIFS($B$2:$B$1534,B146,$G$2:$G$1534,G146,$E$2:$E$1534,">="&(E146-Assumptions!$B$5),$E$2:$E$1534,"<="&(E146+Assumptions!$B$5))>1),1,0) -> 0 | N146: =IF(AND(G146>=Assumptions!$B$4*(1-Assumptions!$B$6),G146<Assumptions!$B$4),1,0) -> 0 | O146: =IF(AND(G146>=Assumptions!$B$7,MOD(G146,Assumptions!$B$7)=0),1,0) -> 0 | P146: =IF(OR(H146="",I146=""),1,0) -> 0 | Q146: =IF(WEEKDAY(F146,2)>5,1,0) -> 0 | R146: =L146*Assumptions!$B$11+M146*Assumptions!$B$12+N146*Assumptions!$B$13+O146*Assumptions!$B$14+P146*Assumptions!$B$15+Q146*Assumptions!$B$16 -> 0 | S146: =IF(R146>=Assumptions!$B$20,"High",IF(R146>=Assumptions!$B$21,"Medium",IF(R146>=1,"Low","Clear"))) -> Clear | T146: =IF(R146=0,"",IF(L146=1,"Duplicate invoice; ","")&IF(M146=1,"Near-duplicate; ","")&IF(N146=1,"Just below limit; ","")&IF(O146=1,"Round amount; ","")&IF(P146=1,"No PO/GRN; ","")&IF(Q146=1,"Weekend payment; ",""))
A147: TXN-0146 | B147: V036 | C147: Vertex Facility Care Pvt Ltd | D147: INV-036-55069 | E147: 45791 | F147: 45820 | G147: 4267.35 | H147: PO497180 | I147: GR497180 | J147: AP-Mgr-02 | K147: =VALUE(LEFT(TEXT(G147,"0"),1)) -> 4 | L147: =IF(COUNTIFS($B$2:$B$1534,B147,$D$2:$D$1534,D147)>1,1,0) -> 0 | M147: =IF(AND(L147=0,COUNTIFS($B$2:$B$1534,B147,$G$2:$G$1534,G147,$E$2:$E$1534,">="&(E147-Assumptions!$B$5),$E$2:$E$1534,"<="&(E147+Assumptions!$B$5))>1),1,0) -> 0 | N147: =IF(AND(G147>=Assumptions!$B$4*(1-Assumptions!$B$6),G147<Assumptions!$B$4),1,0) -> 0 | O147: =IF(AND(G147>=Assumptions!$B$7,MOD(G147,Assumptions!$B$7)=0),1,0) -> 0 | P147: =IF(OR(H147="",I147=""),1,0) -> 0 | Q147: =IF(WEEKDAY(F147,2)>5,1,0) -> 0 | R147: =L147*Assumptions!$B$11+M147*Assumptions!$B$12+N147*Assumptions!$B$13+O147*Assumptions!$B$14+P147*Assumptions!$B$15+Q147*Assumptions!$B$16 -> 0 | S147: =IF(R147>=Assumptions!$B$20,"High",IF(R147>=Assumptions!$B$21,"Medium",IF(R147>=1,"Low","Clear"))) -> Clear | T147: =IF(R147=0,"",IF(L147=1,"Duplicate invoice; ","")&IF(M147=1,"Near-duplicate; ","")&IF(N147=1,"Just below limit; ","")&IF(O147=1,"Round amount; ","")&IF(P147=1,"No PO/GRN; ","")&IF(Q147=1,"Weekend payment; ",""))
A148: TXN-0147 | B148: V004 | C148: Horizon IT Services Pvt Ltd | D148: INV-004-22130 | E148: 45784 | F148: 45821 | G148: 717299.56 | H148: PO449989 | I148: GR449989 | J148: AP-Mgr-04 | K148: =VALUE(LEFT(TEXT(G148,"0"),1)) -> 7 | L148: =IF(COUNTIFS($B$2:$B$1534,B148,$D$2:$D$1534,D148)>1,1,0) -> 0 | M148: =IF(AND(L148=0,COUNTIFS($B$2:$B$1534,B148,$G$2:$G$1534,G148,$E$2:$E$1534,">="&(E148-Assumptions!$B$5),$E$2:$E$1534,"<="&(E148+Assumptions!$B$5))>1),1,0) -> 0 | N148: =IF(AND(G148>=Assumptions!$B$4*(1-Assumptions!$B$6),G148<Assumptions!$B$4),1,0) -> 0 | O148: =IF(AND(G148>=Assumptions!$B$7,MOD(G148,Assumptions!$B$7)=0),1,0) -> 0 | P148: =IF(OR(H148="",I148=""),1,0) -> 0 | Q148: =IF(WEEKDAY(F148,2)>5,1,0) -> 0 | R148: =L148*Assumptions!$B$11+M148*Assumptions!$B$12+N148*Assumptions!$B$13+O148*Assumptions!$B$14+P148*Assumptions!$B$15+Q148*Assumptions!$B$16 -> 0 | S148: =IF(R148>=Assumptions!$B$20,"High",IF(R148>=Assumptions!$B$21,"Medium",IF(R148>=1,"Low","Clear"))) -> Clear | T148: =IF(R148=0,"",IF(L148=1,"Duplicate invoice; ","")&IF(M148=1,"Near-duplicate; ","")&IF(N148=1,"Just below limit; ","")&IF(O148=1,"Round amount; ","")&IF(P148=1,"No PO/GRN; ","")&IF(Q148=1,"Weekend payment; ",""))
...

Sheet Assumptions
A1: Assumptions and parameters
A2: Blue cells are inputs. Change them and every test, count and chart in the workbook recalculates.
A3: Parameter | B3: Value | C3: Note
A4: Approval limit (INR) | B4: 50000 | C4: Assumed single-approver limit. Invoices above this need senior approval. Illustrative value, not from a real client.
A5: Near-duplicate window (days) | B5: 7 | C5: Same vendor + same amount, invoice dates within this many days, different invoice number.
A6: Just-below-limit band (%) | B6: 0.05 | C6: Flag amounts from (limit x (1 - band)) up to the limit. 5% of 50,000 = 47,500 to 49,999.99.
A7: Round-number multiple (INR) | B7: 10000 | C7: Flag amounts that are an exact multiple of this value.
A9: Risk weights (points added to a transaction's score per test failed)
A10: Test | B10: Weight | C10: Rationale
A11: Duplicate invoice | B11: 5 | C11: Strongest indicator of duplicate payment; most direct financial loss.
A12: Near-duplicate | B12: 3 | C12: Same amount and vendor close in time with a different invoice number: a common way duplicates are disguised.
A13: Just below approval limit | B13: 3 | C13: Possible invoice splitting or limit avoidance.
A14: Round-number amount | B14: 1 | C14: Weak on its own. Genuine invoices can be round, so it is weighted low.
A15: No PO / GRN (3-way match failure) | B15: 4 | C15: Payment without purchase order or goods receipt bypasses a core control.
A16: Weekend payment | B16: 1 | C16: Weak on its own. Unusual processing time, worth a look in combination with other flags.
A18: Rating cut-offs
A19: Rating | B19: Minimum score | C19: Note
A20: High | B20: 5 | C20: Score at or above this value is High.
A21: Medium | B21: 3 | C21: Score at or above this value (and below High) is Medium.
A22: Low | B22: 1 | C22: Any other flagged transaction. Score 0 = Clear.

Sheet Vendor_Risk
A1: Vendor risk view
A2: Sorted by flagged transactions when the file was built; the figures themselves are live formulas.
A4: Vendor_ID | B4: Vendor_Name | C4: Transactions | D4: Total value (INR) | E4: Flagged txns | F4: % flagged | G4: Value flagged (INR) | H4: High-risk txns
A5: V020 | B5: Fortis Stationery Pvt Ltd | C5: =COUNTIF(Data!$B$2:$B$1534,A5) -> 48 | D5: =SUMIF(Data!$B$2:$B$1534,A5,Data!$G$2:$G$1534) -> 7764932 | E5: =COUNTIFS(Data!$B$2:$B$1534,A5,Data!$R$2:$R$1534,">0") -> 11 | F5: =IF(C5=0,0,E5/C5) -> 0.22916667 | G5: =SUMIFS(Data!$G$2:$G$1534,Data!$B$2:$B$1534,A5,Data!$R$2:$R$1534,">0") -> 2314909.4 | H5: =COUNTIFS(Data!$B$2:$B$1534,A5,Data!$S$2:$S$1534,"High") -> 4
A6: V030 | B6: Delta Print Media Pvt Ltd | C6: =COUNTIF(Data!$B$2:$B$1534,A6) -> 47 | D6: =SUMIF(Data!$B$2:$B$1534,A6,Data!$G$2:$G$1534) -> 10391465 | E6: =COUNTIFS(Data!$B$2:$B$1534,A6,Data!$R$2:$R$1534,">0") -> 10 | F6: =IF(C6=0,0,E6/C6) -> 0.21276596 | G6: =SUMIFS(Data!$G$2:$G$1534,Data!$B$2:$B$1534,A6,Data!$R$2:$R$1534,">0") -> 3827306.4 | H6: =COUNTIFS(Data!$B$2:$B$1534,A6,Data!$S$2:$S$1534,"High") -> 4
A7: V014 | B7: Westgate Security Services Pvt Ltd | C7: =COUNTIF(Data!$B$2:$B$1534,A7) -> 39 | D7: =SUMIF(Data!$B$2:$B$1534,A7,Data!$G$2:$G$1534) -> 4287707.8 | E7: =COUNTIFS(Data!$B$2:$B$1534,A7,Data!$R$2:$R$1534,">0") -> 6 | F7: =IF(C7=0,0,E7/C7) -> 0.15384615 | G7: =SUMIFS(Data!$G$2:$G$1534,Data!$B$2:$B$1534,A7,Data!$R$2:$R$1534,">0") -> 190294.98 | H7: =COUNTIFS(Data!$B$2:$B$1534,A7,Data!$S$2:$S$1534,"High") -> 4
A8: V026 | B8: Delta Consulting Pvt Ltd | C8: =COUNTIF(Data!$B$2:$B$1534,A8) -> 41 | D8: =SUMIF(Data!$B$2:$B$1534,A8,Data!$G$2:$G$1534) -> 4964671.7 | E8: =COUNTIFS(Data!$B$2:$B$1534,A8,Data!$R$2:$R$1534,">0") -> 11 | F8: =IF(C8=0,0,E8/C8) -> 0.26829268 | G8: =SUMIFS(Data!$G$2:$G$1534,Data!$B$2:$B$1534,A8,Data!$R$2:$R$1534,">0") -> 935919.82 | H8: =COUNTIFS(Data!$B$2:$B$1534,A8,Data!$S$2:$S$1534,"High") -> 2
A9: V029 | B9: Orbit Travel Desk Pvt Ltd | C9: =COUNTIF(Data!$B$2:$B$1534,A9) -> 34 | D9: =SUMIF(Data!$B$2:$B$1534,A9,Data!$G$2:$G$1534) -> 3895760.7 | E9: =COUNTIFS(Data!$B$2:$B$1534,A9,Data!$R$2:$R$1534,">0") -> 8 | F9: =IF(C9=0,0,E9/C9) -> 0.23529412 | G9: =SUMIFS(Data!$G$2:$G$1534,Data!$B$2:$B$1534,A9,Data!$R$2:$R$1534,">0") -> 1075801.8 | H9: =COUNTIFS(Data!$B$2:$B$1534,A9,Data!$S$2:$S$1534,"High") -> 2
A10: V039 | B10: Ironwood Electricals Pvt Ltd | C10: =COUNTIF(Data!$B$2:$B$1534,A10) -> 31 | D10: =SUMIF(Data!$B$2:$B$1534,A10,Data!$G$2:$G$1534) -> 3747618.4 | E10: =COUNTIFS(Data!$B$2:$B$1534,A10,Data!$R$2:$R$1534,">0") -> 7 | F10: =IF(C10=0,0,E10/C10) -> 0.22580645 | G10: =SUMIFS(Data!$G$2:$G$1534,Data!$B$2:$B$1534,A10,Data!$R$2:$R$1534,">0") -> 1299312.9 | H10: =COUNTIFS(Data!$B$2:$B$1534,A10,Data!$S$2:$S$1534,"High") -> 2
A11: V040 | B11: Unity Maintenance Pvt Ltd | C11: =COUNTIF(Data!$B$2:$B$1534,A11) -> 33 | D11: =SUMIF(Data!$B$2:$B$1534,A11,Data!$G$2:$G$1534) -> 5498925.3 | E11: =COUNTIFS(Data!$B$2:$B$1534,A11,Data!$R$2:$R$1534,">0") -> 7 | F11: =IF(C11=0,0,E11/C11) -> 0.21212121 | G11: =SUMIFS(Data!$G$2:$G$1534,Data!$B$2:$B$1534,A11,Data!$R$2:$R$1534,">0") -> 145707.99 | H11: =COUNTIFS(Data!$B$2:$B$1534,A11,Data!$S$2:$S$1534,"High") -> 2
A12: V015 | B12: Westgate Travel Desk Pvt Ltd | C12: =COUNTIF(Data!$B$2:$B$1534,A12) -> 31 | D12: =SUMIF(Data!$B$2:$B$1534,A12,Data!$G$2:$G$1534) -> 4268194.3 | E12: =COUNTIFS(Data!$B$2:$B$1534,A12,Data!$R$2:$R$1534,">0") -> 6 | F12: =IF(C12=0,0,E12/C12) -> 0.19354839 | G12: =SUMIFS(Data!$G$2:$G$1534,Data!$B$2:$B$1534,A12,Data!$R$2:$R$1534,">0") -> 97643.24 | H12: =COUNTIFS(Data!$B$2:$B$1534,A12,Data!$S$2:$S$1534,"High") -> 2
A13: V012 | B13: Trident Office Supplies Pvt Ltd | C13: =COUNTIF(Data!$B$2:$B$1534,A13) -> 43 | D13: =SUMIF(Data!$B$2:$B$1534,A13,Data!$G$2:$G$1534) -> 4939538.2 | E13: =COUNTIFS(Data!$B$2:$B$1534,A13,Data!$R$2:$R$1534,">0") -> 5 | F13: =IF(C13=0,0,E13/C13) -> 0.11627907 | G13: =SUMIFS(Data!$G$2:$G$1534,Data!$B$2:$B$1534,A13,Data!$R$2:$R$1534,">0") -> 289384.85 | H13: =COUNTIFS(Data!$B$2:$B$1534,A13,Data!$S$2:$S$1534,"High") -> 2
A14: V027 | B14: Lumina Catering Pvt Ltd | C14: =COUNTIF(Data!$B$2:$B$1534,A14) -> 41 | D14: =SUMIF(Data!$B$2:$B$1534,A14,Data!$G$2:$G$1534) -> 5703037.7 | E14: =COUNTIFS(Data!$B$2:$B$1534,A14,Data!$R$2:$R$1534,">0") -> 5 | F14: =IF(C14=0,0,E14/C14) -> 0.12195122 | G14: =SUMIFS(Data!$G$2:$G$1534,Data!$B$2:$B$1534,A14,Data!$R$2:$R$1534,">0") -> 75842.66 | H14: =COUNTIFS(Data!$B$2:$B$1534,A14,Data!$S$2:$S$1534,"High") -> 2
A15: V032 | B15: Jaywalk Maintenance Pvt Ltd | C15: =COUNTIF(Data!$B$2:$B$1534,A15) -> 49 | D15: =SUMIF(Data!$B$2:$B$1534,A15,Data!$G$2:$G$1534) -> 4378139.7 | E15: =COUNTIFS(Data!$B$2:$B$1534,A15,Data!$R$2:$R$1534,">0") -> 5 | F15: =IF(C15=0,0,E15/C15) -> 0.10204082 | G15: =SUMIFS(Data!$G$2:$G$1534,Data!$B$2:$B$1534,A15,Data!$R$2:$R$1534,">0") -> 202601.72 | H15: =COUNTIFS(Data!$B$2:$B$1534,A15,Data!$S$2:$S$1534,"High") -> 2
A16: V001 | B16: Unity Logistics Pvt Ltd | C16: =COUNTIF(Data!$B$2:$B$1534,A16) -> 41 | D16: =SUMIF(Data!$B$2:$B$1534,A16,Data!$G$2:$G$1534) -> 4404016.2 | E16: =COUNTIFS(Data!$B$2:$B$1534,A16,Data!$R$2:$R$1534,">0") -> 4 | F16: =IF(C16=0,0,E16/C16) -> 0.097560976 | G16: =SUMIFS(Data!$G$2:$G$1534,Data!$B$2:$B$1534,A16,Data!$R$2:$R$1534,">0") -> 1161955.4 | H16: =COUNTIFS(Data!$B$2:$B$1534,A16,Data!$S$2:$S$1534,"High") -> 2
... A44: V017 | B44: Orbit Catering Pvt Ltd | C44: =COUNTIF(Data!$B$2:$B$1534,A44) -> 34 | D44: =SUMIF(Data!$B$2:$B$1534,A44,Data!$G$2:$G$1534) -> 7255064.5 | E44: =COUNTIFS(Data!$B$2:$B$1534,A44,Data!$R$2:$R$1534,">0") -> 0 | F44: =IF(C44=0,0,E44/C44) -> 0 | G44: =SUMIFS(Data!$G$2:$G$1534,Data!$B$2:$B$1534,A44,Data!$R$2:$R$1534,">0") -> 0 | H44: =COUNTIFS(Data!$B$2:$B$1534,A44,Data!$S$2:$S$1534,"High") -> 0

Sheet Approver_Analysis
A1: Approver analysis
